{
  "comments": [
    {
      "unresolved": false,
      "key": {
        "uuid": "a0fdf3dd_259657f3",
        "filename": "/COMMIT_MSG",
        "patchSetId": 3
      },
      "lineNbr": 9,
      "author": {
        "id": 530
      },
      "writtenOn": "2021-11-23T13:36:48Z",
      "side": 1,
      "message": "correct.\n\nMoreover than ONAP repos are full of tox.ini doppelgangers that needs to be removed.\n\ncf https://gerrit.onap.org/r/c/doc/+/117370",
      "range": {
        "startLine": 9,
        "startChar": 0,
        "endLine": 9,
        "endChar": 60
      },
      "revId": "7120d7e0712b30b14ada8503fc5d6ce0a8a7ca55",
      "serverId": "f2a2391d-0403-4fa5-b183-4056999a8a09"
    },
    {
      "unresolved": false,
      "key": {
        "uuid": "9b83a9d4_5a7d90a3",
        "filename": "/PATCHSET_LEVEL",
        "patchSetId": 3
      },
      "lineNbr": 0,
      "author": {
        "id": 234
      },
      "writtenOn": "2021-11-22T14:09:11Z",
      "side": 1,
      "message": "Bengt: Please fix your verification job ðŸ˜Š\n15:06:24 An unexpected error has occurred: CalledProcessError: command: (\u0027/usr/bin/git\u0027, \u0027fetch\u0027, \u0027origin\u0027, \u0027--tags\u0027)\n15:06:24 return code: 128\n15:06:24 expected return code: 0\n15:06:24 stdout: (none)\n15:06:24 stderr:\n15:06:24     fatal: unable to access \u0027https://gitlab.com/pycqa/flake8/\u0027: The requested URL returned error: 502\n15:06:24",
      "revId": "7120d7e0712b30b14ada8503fc5d6ce0a8a7ca55",
      "serverId": "f2a2391d-0403-4fa5-b183-4056999a8a09"
    },
    {
      "unresolved": false,
      "key": {
        "uuid": "04398e4e_81a1f4fb",
        "filename": "/PATCHSET_LEVEL",
        "patchSetId": 3
      },
      "lineNbr": 0,
      "author": {
        "id": 234
      },
      "writtenOn": "2021-11-22T14:28:35Z",
      "side": 1,
      "message": "recheck / reverify",
      "revId": "7120d7e0712b30b14ada8503fc5d6ce0a8a7ca55",
      "serverId": "f2a2391d-0403-4fa5-b183-4056999a8a09"
    },
    {
      "unresolved": false,
      "key": {
        "uuid": "358bbc6a_56274fb6",
        "filename": "/PATCHSET_LEVEL",
        "patchSetId": 3
      },
      "lineNbr": 0,
      "author": {
        "id": 530
      },
      "writtenOn": "2021-11-23T13:40:55Z",
      "side": 1,
      "message": "I can reach \u0027https://gitlab.com/pycqa/flake8/\u0027 from my home Internet access.\n\nI guess there are proxy or network issues in the gate once again...",
      "parentUuid": "9b83a9d4_5a7d90a3",
      "revId": "7120d7e0712b30b14ada8503fc5d6ce0a8a7ca55",
      "serverId": "f2a2391d-0403-4fa5-b183-4056999a8a09"
    }
  ]
}